<?xml version="1.0" encoding="utf-8"?>
<sdf version='1.6'>
  <model name='argus'>
    <link name='base_link'>
      <pose frame=''>0 0 0 0 -0 0</pose>
      <inertial>
        <pose frame=''>0 0 0.015 0 -0 0</pose>
        <mass>0.606057</mass>
        <inertia>
          <ixx>0.0006</ixx>
          <ixy>0</ixy>
          <ixz>0</ixz>
          <iyy>0.0008</iyy>
          <iyz>0</iyz>
          <izz>0.0008</izz>
        </inertia>
      </inertial>

      <collision name='base_link_collision'>
        <pose frame=''>0 0 0.015 0 -0 0</pose>
        <geometry>
          <box>
            <size>0.2 0.12 0.03</size>
          </box>
        </geometry>
      </collision>

      <visual name='base_link_visual'>
        <pose frame=''>0 0 0.015 0 -0 0</pose>
        <geometry>
          <box>
            <size>0.2 0.12 0.02</size>
          </box>
        </geometry>
        <material>
          <script>
            <name>Gazebo/Grey</name>
            <uri>file://media/materials/scripts/gazebo.material</uri>
          </script>
          <shader type='vertex'>
            <normal_map>__default__</normal_map>
          </shader>
          <ambient>0.3 0.3 0.3 1</ambient>
          <diffuse>0.7 0.7 0.7 1</diffuse>
          <specular>0.01 0.01 0.01 1</specular>
          <emissive>0 0 0 1</emissive>
        </material>
      </visual>
      
      <collision name="caster_collision">
        <pose>-0.05 0 -0.01 0 0 0</pose>
        <geometry>
          <sphere>
            <radius>0.01500</radius>
          </sphere>
        </geometry>
        <surface>
          <friction>
            <ode>
              <mu>10</mu>
              <mu2>10</mu2>
              <fdir1>0 0 0</fdir1>
              <slip1>1.0</slip1>
              <slip2>1.0</slip2>
            </ode>
          </friction>
        </surface>
      </collision>

      <visual name='caster_visual'>
            <pose>-0.05 0 -0.01 0 0 0</pose>
            <geometry>
              <sphere>
                <radius>0.015</radius>
              </sphere>
            </geometry>
          </visual>
    </link>
    
    <link name='camera'>
      <pose frame=''>0.065 0.015 0.084 0 0.56 0</pose>
      <inertial>
        <pose frame=''>0.03266 -0.022303 -8.9e-05 0 -0 0</pose>
        <mass>0.015961</mass>
        <inertia>
          <ixx>1.593e-05</ixx>
          <ixy>-6.2483e-08</ixy>
          <ixz>-2.5912e-09</ixz>
          <iyy>3.5917e-06</iyy>
          <iyz>3.141e-10</iyz>
          <izz>1.5415e-05</izz>
        </inertia>
      </inertial>
      <collision name='camera_collision'>
        <pose frame=''>0 0 0 0 -0 0</pose>
        <geometry>
          <mesh>
            <scale>1 1 1</scale>
            <uri>model://argus/meshes/camera.STL</uri>
          </mesh>
        </geometry>
        <surface>
          <contact>
            <ode/>
          </contact>
          <friction>
            <ode/>
          </friction>
        </surface>
      </collision>
      <visual name='camera_visual'>
        <pose frame=''>0 0 0 0 -0 0</pose>
        <geometry>
          <mesh>
            <scale>1 1 1</scale>
            <uri>model://argus/meshes/camera.STL</uri>
          </mesh>
        </geometry>
        <material>
          <ambient>0.3 0.3 0.3 1</ambient>
          <diffuse>0.3 0.3 0.3 1</diffuse>
          <specular>0 0 0 0</specular>
          <emissive>0 0 0 1</emissive>
        </material>
      </visual>
      <gravity>1</gravity>
      <velocity_decay/>
      <self_collide>0</self_collide>
      <sensor name='camera' type='camera'>
        <update_rate>30</update_rate>
        <camera name='head'>
          <horizontal_fov>1.085595</horizontal_fov>
          <image>
            <width>640</width>
            <height>480</height>
            <format>B8G8R8</format>
          </image>
          <clip>
            <near>0.02</near>
            <far>300</far>
          </clip>
          <noise>
            <type>gaussian</type>
            <mean>0</mean>
            <stddev>0.007</stddev>
          </noise>
        </camera>
        <plugin name='camera_controller' filename='libgazebo_ros_camera.so'>
          <alwaysOn>true</alwaysOn>
          <updateRate>0.0</updateRate>
          <cameraName>camera</cameraName>
          <imageTopicName>image_raw</imageTopicName>
          <cameraInfoTopicName>camera_info</cameraInfoTopicName>
          <frameName>base_link</frameName>
          <hackBaseline>0.07</hackBaseline>
          <distortionK1>0.0</distortionK1>
          <distortionK2>0.0</distortionK2>
          <distortionK3>0.0</distortionK3>
          <distortionT1>0.0</distortionT1>
          <distortionT2>0.0</distortionT2>
        </plugin>
      </sensor>
    </link>
    <joint name='camera' type='revolute'>
      <child>camera</child>
      <parent>base_link</parent>
      <axis>
        <xyz>0 -1 0</xyz>
        <limit>
          <lower>0</lower>
          <upper>0</upper>
          <effort>0</effort>
          <velocity>0</velocity>
        </limit>
        <dynamics>
          <spring_reference>0</spring_reference>
          <spring_stiffness>0</spring_stiffness>
        </dynamics>
        <use_parent_model_frame>1</use_parent_model_frame>
      </axis>
      <physics>
        <ode>
          <limit>
            <cfm>0</cfm>
            <erp>0.2</erp>
          </limit>
        </ode>
      </physics>
    </joint>

    <link name='left_front_wheel'>
      <pose frame=''>0.035 0.0628 0.008 0 -0 0</pose>
      <inertial>
        <pose frame=''>0 0.01 0 0 -0 0</pose>
        <mass>0.035688</mass>
        <inertia>
          <ixx>1.4809e-05</ixx>
          <ixy>2.2984e-21</ixy>
          <ixz>-2.3483e-37</ixz>
          <iyy>2.8086e-05</iyy>
          <iyz>7.9877e-39</iyz>
          <izz>1.4809e-05</izz>
        </inertia>
      </inertial>
      <collision name='left_front_wheel_collision'>
        <pose frame=''>0 0 0 0 -0 0</pose>
        <geometry>
          <mesh>
            <scale>1 1 1</scale>
            <uri>model://argus/meshes/left_front_wheel.STL</uri>
          </mesh>
        </geometry>
      </collision>
      <visual name='left_front_wheel_visual'>
        <pose frame=''>0 0 0 0 -0 0</pose>
        <geometry>
          <mesh>
            <scale>1 1 1</scale>
            <uri>model://argus/meshes/left_front_wheel.STL</uri>
          </mesh>
        </geometry>
        <material>
          <ambient>0.2 0.2 0.2 1</ambient>
          <diffuse>0.2 0.2 0.2 1</diffuse>
          <specular>0 0 0 0</specular>
          <emissive>0 0 0 1</emissive>
        </material>
      </visual>
    </link>
    <joint name='left_front_wheel' type='revolute'>
      <child>left_front_wheel</child>
      <parent>base_link</parent>
      <axis>
        <xyz>0 1 0</xyz>
        <limit>
          <lower>-1e+16</lower>
          <upper>1e+16</upper>
        </limit>
        <dynamics>
          <spring_reference>0</spring_reference>
          <spring_stiffness>0</spring_stiffness>
        </dynamics>
        <use_parent_model_frame>1</use_parent_model_frame>
      </axis>
    </joint>
    <link name='right_front_wheel'>
      <pose frame=''>0.035 -0.068 0.008 0 -0 0</pose>
      <inertial>
        <pose frame=''>-0 -0.01 -0 0 -0 0</pose>
        <mass>0.035688</mass>
        <inertia>
          <ixx>1.4809e-05</ixx>
          <ixy>1.9973e-21</ixy>
          <ixz>-5.6561e-37</ixz>
          <iyy>2.8086e-05</iyy>
          <iyz>1.1192e-37</iyz>
          <izz>1.4809e-05</izz>
        </inertia>
      </inertial>
      <collision name='right_front_wheel_collision'>
        <pose frame=''>0 0 0 0 -0 0</pose>
        <geometry>
          <mesh>
            <scale>1 1 1</scale>
            <uri>model://argus/meshes/right_front_wheel.STL</uri>
          </mesh>
        </geometry>
      </collision>
      <visual name='right_front_wheel_visual'>
        <pose frame=''>0 0 0 0 -0 0</pose>
        <geometry>
          <mesh>
            <scale>1 1 1</scale>
            <uri>model://argus/meshes/right_front_wheel.STL</uri>
          </mesh>
        </geometry>
        <material>
          <ambient>0.2 0.2 0.2 1</ambient>
          <diffuse>0.2 0.2 0.2 1</diffuse>
          <specular>0 0 0 0</specular>
          <emissive>0 0 0 1</emissive>
        </material>
      </visual>
    </link>
    <joint name='right_front_wheel' type='revolute'>
      <child>right_front_wheel</child>
      <parent>base_link</parent>
      <axis>
        <xyz>0 1 0</xyz>
        <limit>
          <lower>-1e+16</lower>
          <upper>1e+16</upper>
        </limit>
        <dynamics>
          <spring_reference>0</spring_reference>
          <spring_stiffness>0</spring_stiffness>
        </dynamics>
        <use_parent_model_frame>1</use_parent_model_frame>
      </axis>
    </joint>
    <static>0</static>
    <plugin name="differential_drive_controller" filename="libgazebo_ros_diff_drive.so">
      <updateRate>100</updateRate>
      <leftJoint>left_front_wheel</leftJoint>
      <rightJoint>right_front_wheel</rightJoint>
      <wheelSeparation>0.129</wheelSeparation>
      <wheelDiameter>0.07</wheelDiameter>
      <wheelAcceleration>0.5</wheelAcceleration>
      <wheelTorque>20</wheelTorque>
      <commandTopic>control/cmd_vel</commandTopic>
      <odometryTopic>odom</odometryTopic>
      <odometryFrame>odom</odometryFrame>
      <robotBaseFrame>base_link</robotBaseFrame>
      <odometrySource>1</odometrySource>
      <publishWheelTF>false</publishWheelTF>
      <publishOdom>true</publishOdom>
      <publishWheelJointState>true</publishWheelJointState>
      <legacyMode>false</legacyMode>
    </plugin>
  </model>
</sdf>
